<sdf version='1.7'>
  <model name='agbot'>
    <link name='base_footprint'>
      <inertial>
        <pose>0.004651 0 0.082204 0 -0 0</pose>
        <mass>10.206</mass>
        <inertia>
          <ixx>1.11088</ixx>
          <ixy>0</ixy>
          <ixz>0.00188574</ixz>
          <iyy>1.1654</iyy>
          <iyz>0</iyz>
          <izz>1.07129</izz>
        </inertia>
      </inertial>
      <collision name='base_footprint_fixed_joint_lump__base_link_collision'>
        <pose>0 0 0.083 0 -0 0</pose>
        <geometry>
          <box>
            <size>0.385 0.275 0.11</size>
          </box>
        </geometry>
        <surface>
          <contact>
            <ode/>
          </contact>
          <friction>
            <ode/>
          </friction>
        </surface>
      </collision>
      <collision name='base_footprint_fixed_joint_lump__caster_wheel_link_collision_1'>
        <pose>0.116667 0 0.041 0 -0 0</pose>
        <geometry>
          <sphere>
            <radius>0.035</radius>
          </sphere>
        </geometry>
        <surface>
          <contact>
            <ode/>
          </contact>
          <friction>
            <ode>
              <mu>0.0001</mu>
              <mu2>0.0001</mu2>
            </ode>
          </friction>
        </surface>
      </collision>
      <collision name='base_footprint_fixed_joint_lump__mast_link_collision_2'>
        <pose>0.125 0 0.133 0 -0 0</pose>
        <geometry>
          <box>
            <size>0.05 0.05 0.01</size>
          </box>
        </geometry>
        <surface>
          <contact>
            <ode/>
          </contact>
          <friction>
            <ode/>
          </friction>
        </surface>
      </collision>
      <collision name='base_footprint_fixed_joint_lump__rgb_camera_collision_3'>
        <pose>0.375 0 0.113 0 -0 0</pose>
        <geometry>
          <mesh>
            <scale>0.0025 0.0025 0.0025</scale>
            <uri>file:///home/albert/rad_ws/install/agbot_description/share/agbot_description/meshes/pi_camera.STL</uri>
          </mesh>
        </geometry>
        <surface>
          <contact>
            <ode/>
          </contact>
          <friction>
            <ode/>
          </friction>
        </surface>
      </collision>
      <visual name='base_footprint_fixed_joint_lump__base_link_visual'>
        <pose>0 0 0.083 0 -0 0</pose>
        <geometry>
          <box>
            <size>0.35 0.25 0.1</size>
          </box>
        </geometry>
        <material>
          <script>
            <name>Gazebo/White</name>
            <uri>file://media/materials/scripts/gazebo.material</uri>
          </script>
        </material>
      </visual>
      <visual name='base_footprint_fixed_joint_lump__caster_wheel_link_visual_1'>
        <pose>0.116667 0 0.041 0 -0 0</pose>
        <geometry>
          <sphere>
            <radius>0.035</radius>
          </sphere>
        </geometry>
        <material>
          <script>
            <name>Gazebo/Yellow</name>
            <uri>file://media/materials/scripts/gazebo.material</uri>
          </script>
        </material>
      </visual>
      <visual name='base_footprint_fixed_joint_lump__mast_link_visual_2'>
        <pose>0.125 0 0.138 0 -0 0</pose>
        <geometry>
          <box>
            <size>0.05 0.05 0.01</size>
          </box>
        </geometry>
        <material>
          <script>
            <name>Gazebo/Purple</name>
            <uri>file://media/materials/scripts/gazebo.material</uri>
          </script>
        </material>
      </visual>
      <visual name='base_footprint_fixed_joint_lump__rgb_camera_visual_3'>
        <pose>0.175 -0.035 0.148 0 1.5708 0</pose>
        <geometry>
          <mesh>
            <scale>0.0025 0.0025 0.0025</scale>
            <uri>file:///home/albert/rad_ws/install/agbot_description/share/agbot_description/meshes/pi_camera.STL</uri>
          </mesh>
        </geometry>
        <material>
          <script>
            <name>Gazebo/Green</name>
            <uri>file://media/materials/scripts/gazebo.material</uri>
          </script>
        </material>
      </visual>
      <sensor name='laser' type='ray'>
        <visualize>1</visualize>
        <update_rate>10</update_rate>
        <ray>
          <scan>
            <horizontal>
              <samples>360</samples>
              <min_angle>-3.14</min_angle>
              <max_angle>3.14</max_angle>
              <resolution>1</resolution>
            </horizontal>
          </scan>
          <range>
            <min>0.3</min>
            <max>12</max>
          </range>
        </ray>
        <plugin name='laser_controller' filename='libgazebo_ros_ray_sensor.so'>
          <ros>
            <argument>~/out:=scan</argument>
          </ros>
          <output_type>sensor_msgs/LaserScan</output_type>
          <frame_name>laser_frame</frame_name>
        </plugin>
        <pose>0.125 0 0.163 0 -0 0</pose>
      </sensor>
      <sensor name='camera_sensor' type='camera'>
        <visualize>1</visualize>
        <update_rate>60</update_rate>
        <plugin name='camera_controller' filename='libgazebo_ros_camera.so'>
          <frame_name>rgb_camera_optical</frame_name>
        </plugin>
        <pose>0.175 0 0.113 0 -0 0</pose>
      </sensor>
    </link>
    <joint name='base_left_wheel_joint' type='revolute'>
      <pose relative_to='base_footprint'>-0.0875 0.15 0.068 0 -0 0</pose>
      <parent>base_footprint</parent>
      <child>left_wheel_link</child>
      <axis>
        <xyz>0 1 0</xyz>
        <limit>
          <lower>-1e+16</lower>
          <upper>1e+16</upper>
        </limit>
        <dynamics>
          <spring_reference>0</spring_reference>
          <spring_stiffness>0</spring_stiffness>
        </dynamics>
      </axis>
    </joint>
    <link name='left_wheel_link'>
      <pose relative_to='base_left_wheel_joint'>0 0 0 0 -0 0</pose>
      <inertial>
        <pose>0 0 0 1.5708 -1.5708 0</pose>
        <mass>1</mass>
        <inertia>
          <ixx>0.000480583</ixx>
          <ixy>0</ixy>
          <ixz>0</ixz>
          <iyy>0.000480583</iyy>
          <iyz>0</iyz>
          <izz>0.0005445</izz>
        </inertia>
      </inertial>
      <collision name='left_wheel_link_collision'>
        <pose>0 0 0 0 -0 0</pose>
        <geometry>
          <mesh>
            <scale>0.002 0.002 0.002</scale>
            <uri>file:///home/albert/rad_ws/install/agbot_description/share/agbot_description/meshes/left_tire.stl</uri>
          </mesh>
        </geometry>
        <surface>
          <contact>
            <ode/>
          </contact>
          <friction>
            <ode/>
          </friction>
        </surface>
      </collision>
      <visual name='left_wheel_link_visual'>
        <pose>0 0 0 0 -0 0</pose>
        <geometry>
          <mesh>
            <scale>0.002 0.002 0.002</scale>
            <uri>file:///home/albert/rad_ws/install/agbot_description/share/agbot_description/meshes/left_tire.stl</uri>
          </mesh>
        </geometry>
        <material>
          <script>
            <name>Gazebo/Black</name>
            <uri>file://media/materials/scripts/gazebo.material</uri>
          </script>
        </material>
      </visual>
    </link>
    <joint name='base_right_wheel_joint' type='revolute'>
      <pose relative_to='base_footprint'>-0.0875 -0.15 0.068 0 -0 0</pose>
      <parent>base_footprint</parent>
      <child>right_wheel_link</child>
      <axis>
        <xyz>0 1 0</xyz>
        <limit>
          <lower>-1e+16</lower>
          <upper>1e+16</upper>
        </limit>
        <dynamics>
          <spring_reference>0</spring_reference>
          <spring_stiffness>0</spring_stiffness>
        </dynamics>
      </axis>
    </joint>
    <link name='right_wheel_link'>
      <pose relative_to='base_right_wheel_joint'>0 0 0 0 -0 0</pose>
      <inertial>
        <pose>0 0 0 1.5708 -1.5708 0</pose>
        <mass>1</mass>
        <inertia>
          <ixx>0.000480583</ixx>
          <ixy>0</ixy>
          <ixz>0</ixz>
          <iyy>0.000480583</iyy>
          <iyz>0</iyz>
          <izz>0.0005445</izz>
        </inertia>
      </inertial>
      <collision name='right_wheel_link_collision'>
        <pose>0 0 0 0 -0 0</pose>
        <geometry>
          <mesh>
            <scale>0.002 0.002 0.002</scale>
            <uri>file:///home/albert/rad_ws/install/agbot_description/share/agbot_description/meshes/right_tire.stl</uri>
          </mesh>
        </geometry>
        <surface>
          <contact>
            <ode/>
          </contact>
          <friction>
            <ode/>
          </friction>
        </surface>
      </collision>
      <visual name='right_wheel_link_visual'>
        <pose>0 0 0 0 -0 0</pose>
        <geometry>
          <mesh>
            <scale>0.002 0.002 0.002</scale>
            <uri>file:///home/albert/rad_ws/install/agbot_description/share/agbot_description/meshes/right_tire.stl</uri>
          </mesh>
        </geometry>
        <material>
          <script>
            <name>Gazebo/Black</name>
            <uri>file://media/materials/scripts/gazebo.material</uri>
          </script>
        </material>
      </visual>
    </link>
    <static>0</static>
    <plugin name='diff_drive' filename='libgazebo_ros_diff_drive.so'>
      <robot_param>robot_description</robot_param>
      <robot_param_node>robot_state_publisher</robot_param_node>
      <parameters>/home/albert/rad_ws/install/agbot_controller/share/agbot_controller/config/agbot_controllers.yaml</parameters>
      <update_rate>50</update_rate>
      <left_joint>base_left_wheel_joint</left_joint>
      <right_joint>base_right_wheel_joint</right_joint>
      <wheel_separation>0.179</wheel_separation>
      <wheel_diameter>0.066</wheel_diameter>
      <max_wheel_torque>200.0</max_wheel_torque>
      <max_wheel_acceleration>10.0</max_wheel_acceleration>
      <publish_odom>1</publish_odom>
      <publish_odom_tf>1</publish_odom_tf>
      <publish_wheel_tf>1</publish_wheel_tf>
      <odometry_topic>odom</odometry_topic>
      <odometry_frame>odom</odometry_frame>
      <robot_base_frame>base_footprint</robot_base_frame>
    </plugin>
  </model>
</sdf>
