<?xml version="1.0" ?>
<!-- =================================================================================== -->
<!-- |    This document was autogenerated by xacro from agbot_full.xacro               | -->
<!-- |    EDITING THIS FILE BY HAND IS NOT RECOMMENDED                                 | -->
<!-- =================================================================================== -->
<robot name="agbot_full">
  <!-- Gazebo ros2_control plugin -->
  <gazebo>
    <plugin filename="libgazebo_ros_diff_drive.so" name="diff_drive">
      <robot_param>robot_description</robot_param>
      <robot_param_node>robot_state_publisher</robot_param_node>
      <parameters>/home/albert/rad_ws/install/agbot_full_controller/share/agbot_full_controller/config/agbot_full_controllers.yaml</parameters>
      <controller_manager_prefix_node_name>controller_manager</controller_manager_prefix_node_name>
      <update_rate>100</update_rate>
      <left_joint>base_left_wheel_joint</left_joint>
      <right_joint>base_right_wheel_joint</right_joint>
      <wheel_separation>0.179</wheel_separation>
      <wheel_diameter>0.066</wheel_diameter>
      <max_wheel_torque>200.0</max_wheel_torque>
      <max_wheel_acceleration>10.0</max_wheel_acceleration>
      <publish_odom>true</publish_odom>
      <publish_odom_tf>true</publish_odom_tf>
      <publish_wheel_tf>true</publish_wheel_tf>
      <odometry_topic>odom</odometry_topic>
      <odometry_frame>odom</odometry_frame>
      <robot_base_frame>base_footprint</robot_base_frame>
    </plugin>
  </gazebo>
  <gazebo>
    <plugin filename="libgazebo_ros2_control.so" name="gazebo_ros2_control">
      <robot_param>robot_description</robot_param>
      <robot_param_node>robot_state_publisher</robot_param_node>
      <parameters>/home/albert/rad_ws/install/agbot_full_controller/share/agbot_full_controller/config/agbot_full_controllers.yaml</parameters>
      <controller_manager_prefix_node_name>controller_manager</controller_manager_prefix_node_name>
    </plugin>
  </gazebo>
  <gazebo reference="rgb_camera">
    <sensor name="camera_sensor" type="camera">
      <pose>0 0 0 0 0 0</pose>
      <visualize>true</visualize>
      <update_rate>60.0</update_rate>
      <camera>
        <horizontal_fov>1.089</horizontal_fov>
        <image>
          <format>R8G8B8</format>
          <width>1024</width>
          <height>768</height>
        </image>
        <clip>
          <near>0.05</near>
          <far>8.0</far>
        </clip>
      </camera>
      <plugin filename="libgazebo_ros_camera.so" name="camera_controller_base">
        <frame_name>rgb_camera_optical_b</frame_name>
      </plugin>
    </sensor>
  </gazebo>
  <gazebo reference="arm_rgb_camera">
    <sensor name="camera_sensor" type="camera">
      <pose>0 0 0 0 0 0</pose>
      <visualize>true</visualize>
      <update_rate>60.0</update_rate>
      <camera>
        <horizontal_fov>1.089</horizontal_fov>
        <image>
          <format>R8G8B8</format>
          <width>1024</width>
          <height>768</height>
        </image>
        <clip>
          <near>0.01</near>
          <far>6.0</far>
        </clip>
      </camera>
      <plugin filename="libgazebo_ros_camera.so" name="camera_controller_arm">
        <frame_name>rgb_camera_optical_a</frame_name>
      </plugin>
    </sensor>
  </gazebo>
  <gazebo reference="laser_frame">
    <sensor name="laser" type="ray">
      <pose> 0 0 0 0 0 0 </pose>
      <visualize>true</visualize>
      <update_rate>10</update_rate>
      <ray>
        <scan>
          <horizontal>
            <samples>360</samples>
            <min_angle>-3.14</min_angle>
            <max_angle>3.14</max_angle>
          </horizontal>
        </scan>
        <range>
          <min>0.3</min>
          <max>12</max>
        </range>
      </ray>
      <plugin filename="libgazebo_ros_ray_sensor.so" name="laser_controller">
        <ros>
          <argument>~/out:=scan</argument>
        </ros>
        <output_type>sensor_msgs/LaserScan</output_type>
        <frame_name>laser_frame</frame_name>
      </plugin>
    </sensor>
  </gazebo>
  <!-- Robot Body -->
  <gazebo reference="base_link">
    <material>Gazebo/White</material>
  </gazebo>
  <gazebo reference="left_wheel_link">
    <material>Gazebo/Black</material>
    <mu1 value="0.8"/>
    <mu2 value="0.8"/>
  </gazebo>
  <gazebo reference="right_wheel_link">
    <material>Gazebo/Black</material>
    <mu1 value="0.8"/>
    <mu2 value="0.8"/>
  </gazebo>
  <gazebo reference="caster_wheel_link">
    <material>Gazebo/Yellow</material>
    <mu1 value="0.0001"/>
    <mu2 value="0.0001"/>
  </gazebo>
  <gazebo reference="rgb_camera">
    <material>Gazebo/DarkGrey</material>
  </gazebo>
  <gazebo reference="mast_link">
    <material>Gazebo/Purple</material>
  </gazebo>
  <!-- Robot Arm -->
  <gazebo reference="arm_base_rail_link">
    <material>Gazebo/White</material>
  </gazebo>
  <gazebo reference="arm_mid_rail_link">
    <material>Gazebo/Black</material>
    <kp>1000000.0</kp>
    <kd>100.0</kd>
    <mu1>30.0</mu1>
    <mu2>30.0</mu2>
    <maxVel>0.5</maxVel>
    <minDepth>0.001</minDepth>
  </gazebo>
  <gazebo reference="arm_base_car_link">
    <material>Gazebo/White</material>
    <kp>1000000.0</kp>
    <kd>100.0</kd>
    <mu1>30.0</mu1>
    <mu2>30.0</mu2>
    <maxVel>0.5</maxVel>
    <minDepth>0.001</minDepth>
  </gazebo>
  <gazebo reference="arm_base_link">
    <material>Gazebo/Blue</material>
  </gazebo>
  <gazebo reference="base_plate">
    <material>Gazebo/Red</material>
  </gazebo>
  <gazebo reference="forward_drive_arm">
    <material>Gazebo/Yellow</material>
  </gazebo>
  <gazebo reference="elbow">
    <material>Gazebo/White</material>
  </gazebo>
  <gazebo reference="horizontal_arm">
    <material>Gazebo/Green</material>
  </gazebo>
  <gazebo reference="claw_support">
    <material>Gazebo/Yellow</material>
  </gazebo>
  <gazebo reference="gripper_right">
    <material>Gazebo/Purple</material>
  </gazebo>
  <gazebo reference="gripper_left">
    <material>Gazebo/Purple</material>
  </gazebo>
  <gazebo reference="arm_rgb_camera">
    <material>Gazebo/Blue</material>
  </gazebo>
  <ros2_control name="RobotSystem" type="system">
    <hardware>
      <plugin>gazebo_ros2_control/GazeboSystem</plugin>
    </hardware>
    <!-- BODY -->
    <joint name="base_left_wheel_joint">
      <command_interface name="velocity"/>
      <state_interface name="position"/>
      <state_interface name="velocity"/>
    </joint>
    <joint name="base_right_wheel_joint">
      <command_interface name="velocity"/>
      <state_interface name="position"/>
      <state_interface name="velocity"/>
    </joint>
    <!-- ARM -->
    <joint name="base_rail_to_ mid_rail_joint">
      <command_interface name="position">
        <param name="min">0</param>
        <param name="max">0.5715</param>
      </command_interface>
      <state_interface name="position"/>
      <state_interface name="velocity"/>
      <state_interface name="effort"/>
    </joint>
    <joint name="mid_rail_to_arm_car_joint">
      <command_interface name="position">
        <param name="min">0</param>
        <param name="max">${(arm_base_rail_length / 2) + (arm_base_rail_length / 4)}</param>
      </command_interface>
      <state_interface name="position"/>
      <state_interface name="velocity"/>
      <state_interface name="effort"/>
    </joint>
    <joint name="arm_base_joint">
      <command_interface name="position">
        <param name="min">-3.14159265359</param>
        <param name="max">3.14159265359</param>
      </command_interface>
      <state_interface name="position"/>
    </joint>
    <joint name="shoulder_joint">
      <command_interface name="position">
        <param name="min">0</param>
        <param name="max">4</param>
      </command_interface>
      <state_interface name="position"/>
    </joint>
    <joint name="elbow_joint">
      <command_interface name="position">
        <param name="min">-3.14159265359</param>
        <param name="max">0</param>
      </command_interface>
      <state_interface name="position"/>
    </joint>
    <joint name="wrist_joint">
      <command_interface name="position">
        <param name="min">-1.570796326795</param>
        <param name="max">1.570796326795</param>
      </command_interface>
      <state_interface name="position"/>
    </joint>
    <joint name="gripper_right_joint">
      <command_interface name="position">
        <param name="min">-1.570796326795</param>
        <param name="max">0</param>
      </command_interface>
      <state_interface name="position"/>
    </joint>
    <joint name="gripper_left_joint">
      <param name="mimic">gripper_right_joint</param>
      <param name="multiplier">-1</param>
      <command_interface name="position">
        <param name="min">0</param>
        <param name="max">1.570796326795</param>
      </command_interface>
    </joint>
  </ros2_control>
  <!-- Init colour -->
  <material name="black">
    <color rgba="0.0 0.0 0.0 1.0"/>
  </material>
  <material name="dark">
    <color rgba="0.3 0.3 0.3 1.0"/>
  </material>
  <material name="light_black">
    <color rgba="0.4 0.4 0.4 1.0"/>
  </material>
  <material name="blue">
    <color rgba="0.0 0.0 0.8 1.0"/>
  </material>
  <material name="green">
    <color rgba="0.0 0.8 0.0 1.0"/>
  </material>
  <material name="grey">
    <color rgba="0.5 0.5 0.5 1.0"/>
  </material>
  <material name="ClearGrey">
    <color rgba="0.2 0.2 0.2 0.75"/>
  </material>
  <material name="orange">
    <color rgba="1.0 0.4235 0.0392 1.0"/>
  </material>
  <material name="brown">
    <color rgba="0.8706 0.8118 0.7647 1.0"/>
  </material>
  <material name="white">
    <color rgba="1.0 1.0 1.0 1.0"/>
  </material>
  <material name="yellow">
    <color rgba="1.0 0.93 0.7 1"/>
  </material>
  <material name="purple">
    <color rgba="0.4 0.23 0.72 1"/>
  </material>
  <material name="turquoise">
    <color rgba="0.05 0.737 0.690 1.0"/>
  </material>
  <material name="skyblue">
    <color rgba="0.2 1.0 1.0"/>
  </material>
  <material name="pink">
    <color rgba="1.0 0 1.0 1.0"/>
  </material>
  <material name="red">
    <color rgba="1 0 0 1"/>
  </material>
  <material name="darkmaroon">
    <color rgba="0.23529411764705882 0.0 0.03137254901960784 1.0"/>
  </material>
  <material name="maroon">
    <color rgba="0.396078431372549 0.0 0.12941176470588237 1.0"/>
  </material>
  <!-- Robot Body -->
  <link name="base_footprint"/>
  <link name="base_link">
    <visual>
      <geometry>
        <box size="1.8288 1.8288 0.762"/>
      </geometry>
      <origin rpy="0 0 0" xyz="0 0 0.381"/>
      <material name="maroon"/>
    </visual>
    <collision>
      <geometry>
        <box size="2.01168 2.01168 0.8382000000000001"/>
      </geometry>
      <origin rpy="0 0 0" xyz="0 0 0.381"/>
    </collision>
    <inertial>
      <origin rpy="0 0 0" xyz="0 0 0.381"/>
      <mass value="18.0"/>
      <inertia ixx="5.88773016" ixy="0" ixz="0" iyy="10.03352832" iyz="0" izz="5.88773016"/>
    </inertial>
  </link>
  <link name="left_wheel_link">
    <visual>
      <geometry>
        <mesh filename="file:///home/albert/rad_ws/install/agbot_full_description/share/agbot_full_description/meshes/left_tire.stl" scale="0.01 0.01 0.01"/>
      </geometry>
      <origin rpy="0 0 0" xyz="0 0 0"/>
      <material name="black"/>
    </visual>
    <collision>
      <geometry>
        <mesh filename="file:///home/albert/rad_ws/install/agbot_full_description/share/agbot_full_description/meshes/left_tire.stl" scale="0.01 0.01 0.01"/>
      </geometry>
      <origin rpy="0 0 0" xyz="0 0 0"/>
    </collision>
    <inertial>
      <origin rpy="1.5707963267948966 -1.5707963267948966 0" xyz="0 0 0"/>
      <mass value="1.0"/>
      <inertia ixx="0.006769333333333333" ixy="0" ixz="0" iyy="0.006769333333333333" iyz="0" izz="0.013122"/>
    </inertial>
  </link>
  <link name="right_wheel_link">
    <visual>
      <geometry>
        <mesh filename="file:///home/albert/rad_ws/install/agbot_full_description/share/agbot_full_description/meshes/right_tire.stl" scale="0.01 0.01 0.01"/>
      </geometry>
      <origin rpy="0 0 0" xyz="0 0 0"/>
      <material name="black"/>
    </visual>
    <collision>
      <geometry>
        <mesh filename="file:///home/albert/rad_ws/install/agbot_full_description/share/agbot_full_description/meshes/right_tire.stl" scale="0.01 0.01 0.01"/>
      </geometry>
      <origin rpy="0 0 0" xyz="0 0 0"/>
    </collision>
    <inertial>
      <origin rpy="1.5707963267948966 -1.5707963267948966 0" xyz="0 0 0"/>
      <mass value="1.0"/>
      <inertia ixx="0.006769333333333333" ixy="0" ixz="0" iyy="0.006769333333333333" iyz="0" izz="0.013122"/>
    </inertial>
  </link>
  <link name="caster_wheel_link">
    <visual>
      <geometry>
        <sphere radius="0.162"/>
      </geometry>
      <origin rpy="0 0 0" xyx="0.6096 0 0.162"/>
      <material name="yellow"/>
    </visual>
    <collision>
      <geometry>
        <sphere radius="0.162"/>
      </geometry>
      <origin rpy="0 0 0" xyx="0.6096 0 0.162"/>
    </collision>
    <inertial>
      <origin rpy="0 0 0" xyz="0.6096 0 0"/>
      <mass value="0.2"/>
      <inertia ixx="0.00209952" ixy="0" ixz="0" iyy="0.00209952" iyz="0" izz="0.00209952"/>
    </inertial>
  </link>
  <link name="rgb_camera_optical">
    </link>
  <link name="rgb_camera">
    <inertial>
      <origin rpy="0 0 0" xyz="0 0 0"/>
      <mass value="0.001"/>
      <inertia ixx="1.0" ixy="0.0" ixz="0.0" iyy="1.0" iyz="0.0" izz="1.0"/>
    </inertial>
    <visual>
      <origin rpy="0 1.5707963267948966 0" xyz="0 -0.035 0.035"/>
      <geometry>
        <mesh filename="file:///home/albert/rad_ws/install/agbot_full_description/share/agbot_full_description/meshes/pi_camera.STL" scale="0.0025 0.0025 0.0025"/>
      </geometry>
      <material name="grey"/>
    </visual>
    <collision>
      <origin rpy="0 0 0" xyz="0.2 0 0"/>
      <geometry>
        <mesh filename="file:///home/albert/rad_ws/install/agbot_full_description/share/agbot_full_description/meshes/pi_camera.STL" scale="0.0025 0.0025 0.0025"/>
      </geometry>
    </collision>
  </link>
  <link name="mast_link">
    <visual>
      <origin rpy="0 0 0" xyz="0 0 0.015"/>
      <geometry>
        <box size="0.05 0.05 0.03"/>
      </geometry>
      <material name="pink"/>
    </visual>
    <collision>
      <geometry>
        <box size="0.05 0.05 0.03"/>
      </geometry>
      <origin rpy="0 0 0" xyz="0 0 0"/>
    </collision>
    <inertial>
      <origin rpy="0 0 0" xyz="0 0 0"/>
      <mass value="0.005"/>
      <inertia ixx="1.416666666666667e-06" ixy="0" ixz="0" iyy="2.083333333333334e-06" iyz="0" izz="1.416666666666667e-06"/>
    </inertial>
  </link>
  <link name="laser_frame">       
    </link>
  <link name="box_one_link">
    <visual>
      <geometry>
        <box size="0.28 0.1524 0.0762"/>
      </geometry>
      <origin rpy="0 0 0" xyz="0 0 0.0381"/>
      <material name="brown"/>
    </visual>
    <collision>
      <geometry>
        <box size="0.30800000000000005 0.16764 0.08382"/>
      </geometry>
      <origin rpy="0 0 0" xyz="0 0 0.0381"/>
    </collision>
    <inertial>
      <origin rpy="0 0 0" xyz="0 0 0.0381"/>
      <mass value="10.0"/>
      <inertia ixx="0.07017203333333334" ixy="0" ixz="0" iyy="0.08468813333333335" iyz="0" izz="0.024193500000000003"/>
    </inertial>
  </link>
  <link name="box_two_link">
    <visual>
      <geometry>
        <box size="0.28 0.1524 0.0762"/>
      </geometry>
      <origin rpy="0 0 0" xyz="0 0 0.0381"/>
      <material name="brown"/>
    </visual>
    <collision>
      <geometry>
        <box size="0.30800000000000005 0.16764 0.08382"/>
      </geometry>
      <origin rpy="0 0 0" xyz="0 0 0.0381"/>
    </collision>
    <inertial>
      <origin rpy="0 0 0" xyz="0 0 0.0381"/>
      <mass value="10.0"/>
      <inertia ixx="0.07017203333333334" ixy="0" ixz="0" iyy="0.08468813333333335" iyz="0" izz="0.024193500000000003"/>
    </inertial>
  </link>
  <link name="box_three_link">
    <visual>
      <geometry>
        <box size="0.28 0.1524 0.0762"/>
      </geometry>
      <origin rpy="0 0 0" xyz="0 0 0.0381"/>
      <material name="brown"/>
    </visual>
    <collision>
      <geometry>
        <box size="0.30800000000000005 0.16764 0.08382"/>
      </geometry>
      <origin rpy="0 0 0" xyz="0 0 0.0381"/>
    </collision>
    <inertial>
      <origin rpy="0 0 0" xyz="0 0 0.0381"/>
      <mass value="10.0"/>
      <inertia ixx="0.07017203333333334" ixy="0" ixz="0" iyy="0.08468813333333335" iyz="0" izz="0.024193500000000003"/>
    </inertial>
  </link>
  <link name="box_four_link">
    <visual>
      <geometry>
        <box size="0.28 0.1524 0.0762"/>
      </geometry>
      <origin rpy="0 0 0" xyz="0 0 0.0381"/>
      <material name="brown"/>
    </visual>
    <collision>
      <geometry>
        <box size="0.30800000000000005 0.16764 0.08382"/>
      </geometry>
      <origin rpy="0 0 0" xyz="0 0 0.0381"/>
    </collision>
    <inertial>
      <origin rpy="0 0 0" xyz="0 0 0.0381"/>
      <mass value="10.0"/>
      <inertia ixx="0.07017203333333334" ixy="0" ixz="0" iyy="0.08468813333333335" iyz="0" izz="0.024193500000000003"/>
    </inertial>
  </link>
  <link name="roboball_cylinder">
    <visual>
      <geometry>
        <cylinder length="1.8288" radius="0.2032"/>
      </geometry>
      <origin rpy="0 0 0" xyz="0 0 0"/>
      <material name="ClearGrey"/>
    </visual>
    <collision>
      <geometry>
        <cylinder length="1.8288" radius="0.2032"/>
      </geometry>
      <origin rpy="0 0 0" xyz="0 0 0"/>
    </collision>
    <inertial>
      <origin rpy="0 0 0" xyz="0 0 0"/>
      <mass value="0.01"/>
      <inertia ixx="0.0028903168" ixy="0" ixz="0" iyy="0.0028903168" iyz="0" izz="0.0002064512"/>
    </inertial>
  </link>
  <link name="arm_base_rail_link">
    <visual>
      <geometry>
        <box size="1.524 0.1524 0.0127"/>
      </geometry>
      <origin rpy="0 0 0" xyz="0 0 0"/>
      <material name="white"/>
    </visual>
    <collision>
      <geometry>
        <box size="1.524 0.1524 0.0127"/>
      </geometry>
      <origin rpy="0 0 0" xyz="0 0 0"/>
    </collision>
    <inertial>
      <origin rpy="0 0 0" xyz="0 0 0.00635"/>
      <mass value="2.0"/>
      <inertia ixx="0.38712288166666664" ixy="0" ixz="0" iyy="0.39096696" iyz="0" izz="0.003897841666666667"/>
    </inertial>
  </link>
  <link name="arm_mid_rail_link">
    <visual>
      <geometry>
        <box size="1.524 0.1524 0.0127"/>
      </geometry>
      <origin rpy="0 0 0" xyz="0 0 0"/>
      <material name="black"/>
    </visual>
    <collision>
      <geometry>
        <box size="1.524 0.1524 0.0127"/>
      </geometry>
      <origin rpy="0 0 0" xyz="0 0 0"/>
    </collision>
    <inertial>
      <origin rpy="0 0 0" xyz="0 0 0.00635"/>
      <mass value="2.0"/>
      <inertia ixx="0.38712288166666664" ixy="0" ixz="0" iyy="0.39096696" iyz="0" izz="0.003897841666666667"/>
    </inertial>
  </link>
  <link name="arm_base_car_link">
    <visual>
      <geometry>
        <box size="1.524 0.1524 0.0127"/>
      </geometry>
      <origin rpy="0 0 0" xyz="0 0 0.00635"/>
      <material name="white"/>
    </visual>
    <collision>
      <geometry>
        <box size="1.524 0.1524 0.0127"/>
      </geometry>
      <origin rpy="0 0 0" xyz="0 0 0.00635"/>
    </collision>
    <inertial>
      <origin rpy="0 0 0" xyz="0 0 0.00635"/>
      <mass value="2.0"/>
      <inertia ixx="0.38712288166666664" ixy="0" ixz="0" iyy="0.39096696" iyz="0" izz="0.003897841666666667"/>
    </inertial>
  </link>
  <link name="arm_base_link">
    <inertial>
      <origin rpy="0 0 0" xyz="0 0 0"/>
      <mass value="1.0"/>
      <inertia ixx="1.0" ixy="0.0" ixz="0.0" iyy="1.0" iyz="0.0" izz="1.0"/>
    </inertial>
    <visual>
      <origin rpy="0 0 0" xyz="-0.077 -0.075 0"/>
      <geometry>
        <mesh filename="file:///home/albert/rad_ws/install/agbot_description/share/agbot_description/meshes/basement.STL" scale="0.0015 0.0015 0.002"/>
      </geometry>
      <material name="blue"/>
    </visual>
    <collision>
      <origin rpy="0 0 0" xyz="-0.075 -.075 0"/>
      <geometry>
        <mesh filename="file:///home/albert/rad_ws/install/agbot_description/share/agbot_description/meshes/basement.STL" scale="0.0015 0.0015 0.002"/>
      </geometry>
    </collision>
  </link>
  <link name="base_plate">
    <inertial>
      <origin rpy="0 0 0" xyz="0 0 0"/>
      <mass value="0.1"/>
      <inertia ixx="1.0" ixy="0.0" ixz="0.0" iyy="1.0" iyz="0.0" izz="1.0"/>
    </inertial>
    <visual>
      <origin rpy="0 0 0" xyz="-0.059 -0.060 -0.121"/>
      <geometry>
        <mesh filename="file:///home/albert/rad_ws/install/agbot_description/share/agbot_description/meshes/base_plate.STL" scale="0.0015 0.0015 0.002"/>
      </geometry>
      <material name="red"/>
    </visual>
    <collision>
      <origin rpy="0 0 0" xyz="-0.076 -0.0798 -0.121"/>
      <geometry>
        <mesh filename="file:///home/albert/rad_ws/install/agbot_description/share/agbot_description/meshes/base_plate.STL" scale="0.0015 0.0015 0.002"/>
      </geometry>
    </collision>
  </link>
  <link name="forward_drive_arm">
    <inertial>
      <origin rpy="0 0 0" xyz="0 0 0"/>
      <mass value="0.1"/>
      <inertia ixx="1.0" ixy="0.0" ixz="0.0" iyy="1.0" iyz="0.0" izz="1.0"/>
    </inertial>
    <visual>
      <origin rpy="0 1.570796326795 1.570796326795" xyz="-0.005 -0.006 0.38"/>
      <geometry>
        <box size="0.75 0.05 0.005"/>
      </geometry>
      <material name="yellow"/>
    </visual>
    <collision>
      <origin rpy="0 1.570796326795 1.570796326795" xyz="0.01 -0.006 0.38"/>
      <geometry>
        <box size="0.75 0.05 0.005"/>
      </geometry>
    </collision>
  </link>
  <link name="elbow">
    <visual>
      <origin rpy="0 1.570796326795 0" xyz="0 0 0"/>
      <geometry>
        <cylinder length="0.18" radius="0.015"/>
      </geometry>
      <material name="white"/>
    </visual>
    <collision>
      <origin rpy="0 1.570796326795 0" xyz="0 0 0"/>
      <geometry>
        <cylinder length="0.18" radius="0.015"/>
      </geometry>
    </collision>
    <inertial>
      <origin rpy="0 0 0" xyz="0 0 0"/>
      <mass value="0.05"/>
      <inertia ixx="0.0001378125" ixy="0" ixz="0" iyy="0.0001378125" iyz="0" izz="5.625e-06"/>
    </inertial>
  </link>
  <link name="horizontal_arm">
    <inertial>
      <origin rpy="0 0 0" xyz="0 0 0"/>
      <mass value="0.1"/>
      <inertia ixx="1.0" ixy="0.0" ixz="0.0" iyy="1.0" iyz="0.0" izz="1.0"/>
    </inertial>
    <visual>
      <origin rpy="0 1.570796326795 1.570796326795" xyz="0 0 0.275"/>
      <geometry>
        <box size="0.555 0.05 0.005"/>
      </geometry>
      <material name="green"/>
    </visual>
    <collision>
      <origin rpy="0 1.570796326795 1.570796326795" xyz="0 0 0.275"/>
      <geometry>
        <box size="0.555 0.05 0.005"/>
      </geometry>
    </collision>
  </link>
  <link name="wrist">
    <visual>
      <origin rpy="0 1.570796326795 0" xyz="0 0 0"/>
      <geometry>
        <cylinder length="0.09" radius="0.015"/>
      </geometry>
      <material name="white"/>
    </visual>
    <collision>
      <origin rpy="0 1.570796326795 0" xyz="0 0 0"/>
      <geometry>
        <cylinder length="0.18" radius="0.015"/>
      </geometry>
    </collision>
    <inertial>
      <origin rpy="0 0 0" xyz="0 0 0"/>
      <mass value="0.05"/>
      <inertia ixx="0.0001378125" ixy="0" ixz="0" iyy="0.0001378125" iyz="0" izz="5.625e-06"/>
    </inertial>
  </link>
  <link name="claw_support">
    <inertial>
      <origin rpy="0 0 0" xyz="0 0 0"/>
      <mass value="0.05"/>
      <inertia ixx="1.0" ixy="0.0" ixz="0.0" iyy="1.0" iyz="0.0" izz="1.0"/>
    </inertial>
    <visual>
      <origin rpy="0 -1.570796326795 -1.570796326795" xyz="-0.048648648648648644 0 0"/>
      <geometry>
        <mesh filename="file:///home/albert/rad_ws/install/agbot_full_description/share/agbot_full_description/meshes/claw_support.STL" scale="0.004 0.004 0.004"/>
      </geometry>
      <material name="pink"/>
    </visual>
    <collision>
      <origin rpy="0 -1.570796326795 -1.570796326795" xyz="-0.048648648648648644 0 0"/>
      <geometry>
        <mesh filename="file:///home/albert/rad_ws/install/agbot_full_description/share/agbot_full_description/meshes/claw_support.STL" scale="0.004 0.004 0.004"/>
      </geometry>
    </collision>
  </link>
  <link name="gripper_right">
    <inertial>
      <origin rpy="0 0 0" xyz="0 0 0"/>
      <mass value="0.01"/>
      <inertia ixx="1.0" ixy="0.0" ixz="0.0" iyy="1.0" iyz="0.0" izz="1.0"/>
    </inertial>
    <visual>
      <origin rpy="0 1.570796326795 1.570796326795" xyz="0.041 0 0.19"/>
      <geometry>
        <mesh filename="file:///home/albert/rad_ws/install/agbot_full_description/share/agbot_full_description/meshes/right_finger.STL" scale="0.004 0.004 0.004"/>
      </geometry>
      <material name="purple"/>
    </visual>
    <collision>
      <origin rpy="0 1.570796326795 1.570796326795" xyz="0.041 0 0.19"/>
      <geometry>
        <mesh filename="file:///home/albert/rad_ws/install/agbot_full_description/share/agbot_full_description/meshes/right_finger.STL" scale="0.004 0.004 0.004"/>
      </geometry>
    </collision>
  </link>
  <link name="gripper_left">
    <inertial>
      <origin rpy="0 0 0" xyz="0 0 0"/>
      <mass value="0.01"/>
      <inertia ixx="1.0" ixy="0.0" ixz="0.0" iyy="1.0" iyz="0.0" izz="1.0"/>
    </inertial>
    <visual>
      <origin rpy="0 1.570796326795 1.570796326795" xyz="0.0147 0 0.19"/>
      <geometry>
        <mesh filename="file:///home/albert/rad_ws/install/agbot_full_description/share/agbot_full_description/meshes/left_finger.STL" scale="0.004 0.004 0.004"/>
      </geometry>
      <material name="purple"/>
    </visual>
    <collision>
      <origin rpy="0 1.570796326795 1.570796326795" xyz="0.0147 0 0.19"/>
      <geometry>
        <mesh filename="file:///home/albert/rad_ws/install/agbot_full_description/share/agbot_full_description/meshes/left_finger.STL" scale="0.004 0.004 0.004"/>
      </geometry>
    </collision>
  </link>
  <link name="arm_rgb_camera_optical">
    </link>
  <link name="arm_rgb_camera">
    <inertial>
      <origin rpy="0 0 0" xyz="0 0 0"/>
      <mass value="0.001"/>
      <inertia ixx="1.0" ixy="0.0" ixz="0.0" iyy="1.0" iyz="0.0" izz="1.0"/>
    </inertial>
    <visual>
      <origin rpy="0 1.570796326795 0" xyz="-0.03 -0.028 0.025"/>
      <geometry>
        <mesh filename="file:///home/albert/rad_ws/install/agbot_full_description/share/agbot_full_description/meshes/pi_camera.STL" scale="0.002 0.002 0.002"/>
      </geometry>
      <material name="blue"/>
    </visual>
    <collision>
      <origin rpy="0 1.570796326795 0" xyz="-0.03 -0.028 0.025"/>
      <geometry>
        <mesh filename="file:///home/albert/rad_ws/install/agbot_full_description/share/agbot_full_description/meshes/pi_camera.STL" scale="0.002 0.002 0.002"/>
      </geometry>
    </collision>
  </link>
  <!-- Joint Descriptions -->
  <!-- Robot Body -->
  <joint name="base_joint" type="fixed">
    <parent link="base_footprint"/>
    <child link="base_link"/>
    <origin rpy="0 0 0" xyz="0 0 0.162"/>
  </joint>
  <joint name="base_right_wheel_joint" type="continuous">
    <parent link="base_link"/>
    <child link="right_wheel_link"/>
    <origin rpy="0 0 0" xyz="-0.4572 -0.9394 0.162"/>
    <axis xyz="0 1 0"/>
  </joint>
  <joint name="base_left_wheel_joint" type="continuous">
    <parent link="base_link"/>
    <child link="left_wheel_link"/>
    <origin rpy="0 0 0" xyz="-0.4572 0.9394 0.162"/>
    <axis xyz="0 1 0"/>
  </joint>
  <joint name="base_caster_wheel_joint" type="fixed">
    <parent link="base_link"/>
    <child link="caster_wheel_link"/>
    <origin rpy="0 0 0" xyz="0.6096 0 0"/>
  </joint>
  <joint name="camera_optical_joint" type="fixed">
    <parent link="base_link"/>
    <child link="rgb_camera_optical"/>
    <origin rpy="0 0 0" xyz="0.9144 0 0.6858"/>
  </joint>
  <joint name="rgb_camera_joint" type="fixed">
    <parent link="rgb_camera_optical"/>
    <child link="rgb_camera"/>
    <origin rpy="0 0 0" xyz="0 0 0"/>
  </joint>
  <joint name="base_mast_joint" type="fixed">
    <parent link="base_link"/>
    <child link="mast_link"/>
    <origin rpy="0 0 0" xyz="0.9394 0 0.5715"/>
  </joint>
  <joint name="laser_joint" type="fixed">
    <parent link="mast_link"/>
    <child link="laser_frame"/>
    <origin rpy="0 0 0" xyz="0 0 0"/>
  </joint>
  <!-- Transition Joint  -->
  <joint name="robo_cylinder_joint" type="fixed">
    <parent link="base_link"/>
    <child link="roboball_cylinder"/>
    <origin rpy="1.570796326795 0 0" xyz="0 0 0.9652000000000001"/>
  </joint>
  <joint name="body_arm_joint" type="fixed">
    <parent link="base_link"/>
    <child link="arm_base_rail_link"/>
    <origin rpy="0 0 1.570796326795" xyz="0 0 0.8001"/>
  </joint>
  <joint name="base_rail_to_ mid_rail_joint" type="prismatic">
    <parent link="arm_base_rail_link"/>
    <child link="arm_mid_rail_link"/>
    <origin rpy="0 0 0" xyz="0 0 0.0127"/>
    <limit effort="100.0" lower="0" upper="0.5715" velocity="0.5"/>
  </joint>
  <joint name="box_one_joint" type="fixed">
    <parent link="arm_base_car_link"/>
    <child link="box_one_link"/>
    <origin rpy="0 0 0" xyz="-0.622 0 0.0127"/>
  </joint>
  <joint name="box_two_joint" type="fixed">
    <parent link="arm_base_car_link"/>
    <child link="box_two_link"/>
    <origin rpy="0 0 0" xyz="-0.292 0 0.0127"/>
  </joint>
  <joint name="box_three_joint" type="fixed">
    <parent link="arm_base_car_link"/>
    <child link="box_three_link"/>
    <origin rpy="0 0 0" xyz="0.09000000000000001 0 0.0127"/>
  </joint>
  <joint name="box_four_joint" type="fixed">
    <parent link="arm_base_car_link"/>
    <child link="box_four_link"/>
    <origin rpy="0 0 0" xyz="0.42000000000000004 0 0.0127"/>
  </joint>
  <!-- Robot Arm -->
  <joint name="mid_rail_to_arm_car_joint" type="prismatic">
    <parent link="arm_mid_rail_link"/>
    <child link="arm_base_car_link"/>
    <origin rpy="0 0 0" xyz="0 0 0.0127"/>
    <limit effort="100.0" lower="0" upper="1.143" velocity="0.5"/>
  </joint>
  <joint name="arm_car_to_arm_base_joint" type="fixed">
    <parent link="arm_base_car_link"/>
    <child link="arm_base_link"/>
    <origin rpy="0 0 1.570796326795" xyz="0.6858 0 0.0127"/>
  </joint>
  <joint name="arm_base_joint" type="revolute">
    <parent link="arm_base_link"/>
    <child link="base_plate"/>
    <origin xyz="0 0 0.07"/>
    <axis xyz="0 0 1"/>
    <limit effort="30.0" lower="-3.14159265359" upper="3.14159265359" velocity="10.0"/>
  </joint>
  <joint name="shoulder_joint" type="revolute">
    <parent link="base_plate"/>
    <child link="forward_drive_arm"/>
    <origin rpy="-1.570796326795 0 0" xyz="0 0 0.075"/>
    <axis xyz="1 0 0"/>
    <limit effort="30.0" lower="0" upper="4.0" velocity="10.0"/>
  </joint>
  <joint name="shoulder_elbow_joint" type="fixed">
    <parent link="forward_drive_arm"/>
    <child link="elbow"/>
    <origin rpy="0 0 0" xyz="0.05333333333333333 0 0.75"/>
  </joint>
  <joint name="elbow_joint" type="revolute">
    <parent link="elbow"/>
    <child link="horizontal_arm"/>
    <origin rpy="-3.14159265359 0 0" xyz="0.045 0 0"/>
    <axis xyz="1 0 0"/>
    <limit effort="30.0" lower="-3.14159265359" upper="0" velocity="10.0"/>
  </joint>
  <joint name="elbow_forearm_joint" type="fixed">
    <parent link="horizontal_arm"/>
    <child link="wrist"/>
    <origin rpy="0 0 0" xyz="0 0 0.555"/>
  </joint>
  <joint name="wrist_joint" type="revolute">
    <parent link="wrist"/>
    <child link="claw_support"/>
    <origin xyz="0 0 0"/>
    <axis xyz="1 0 0"/>
    <limit effort="30.0" lower="-1.570796326795" upper="1.570796326795" velocity="10.0"/>
  </joint>
  <joint name="gripper_right_joint" type="revolute">
    <parent link="claw_support"/>
    <child link="gripper_right"/>
    <origin xyz="-0.035 -0.014 0.083"/>
    <axis xyz="0 1 0"/>
    <limit effort="30.0" lower="-1.570796326795" upper="0.0" velocity="10.0"/>
  </joint>
  <joint name="gripper_left_joint" type="revolute">
    <mimic joint="gripper_right_joint" multiplier="-1"/>
    <parent link="claw_support"/>
    <child link="gripper_left"/>
    <origin xyz="0.040 -0.014 0.083"/>
    <axis xyz="0 1 0"/>
    <limit effort="30.0" lower="0.0" upper="1.570796326795" velocity="10.0"/>
  </joint>
  <joint name="arm_camera_optical_joint" type="fixed">
    <parent link="claw_support"/>
    <child link="arm_rgb_camera_optical"/>
    <origin rpy="0 0 0" xyz="0 .10 0.085"/>
  </joint>
  <joint name="arm_rgb_camera_joint" type="fixed">
    <parent link="arm_rgb_camera_optical"/>
    <child link="arm_rgb_camera"/>
    <origin rpy="0 -1.570796326795 0" xyz="0 0 0.03"/>
  </joint>
  <transmission name="transmission_base_right_wheel_joint">
    <!-- <plugin>transmission_interface/DifferentialTransmission</plugin> -->
    <plugin>transmission_interface/SimpleTransmission</plugin>
    <actuator name="motor_base_right_wheel_joint" role="actuator1"/>
    <joint name="base_right_wheel_joint" role="joint1">
      <mechanical_reduction>1.0</mechanical_reduction>
    </joint>
  </transmission>
  <transmission name="transmission_base_left_wheel_joint">
    <!-- <plugin>transmission_interface/DifferentialTransmission</plugin> -->
    <plugin>transmission_interface/SimpleTransmission</plugin>
    <actuator name="motor_base_left_wheel_joint" role="actuator1"/>
    <joint name="base_left_wheel_joint" role="joint1">
      <mechanical_reduction>1.0</mechanical_reduction>
    </joint>
  </transmission>
  <transmission name="mid_rail_joint_prismatic_transmission">
    <type>transmission_interface/SimpleTransmission</type>
    <!-- <plugin>hardware_interface/VelocityJointInterface</plugin> -->
    <joint name="mid_rail_joint">
      <hardwareInterface>hardware_interface/PositionJointInterface</hardwareInterface>
    </joint>
    <actuator name="mid_rail_joint_motor">
      <hardwareInterface>hardware_interface/PositionJointInterface</hardwareInterface>
      <mechanicalReduction>1</mechanicalReduction>
    </actuator>
  </transmission>
  <transmission name="arm_base_to_arm_car_joint_prismatic_transmission">
    <type>transmission_interface/SimpleTransmission</type>
    <!-- <plugin>hardware_interface/VelocityJointInterface</plugin> -->
    <joint name="arm_base_to_arm_car_joint">
      <hardwareInterface>hardware_interface/PositionJointInterface</hardwareInterface>
    </joint>
    <actuator name="arm_base_to_arm_car_joint_motor">
      <hardwareInterface>hardware_interface/PositionJointInterface</hardwareInterface>
      <mechanicalReduction>1</mechanicalReduction>
    </actuator>
  </transmission>
  <transmission name="transmission_arm_base_joint">
    <!-- <plugin>transmission_interface/DifferentialTransmission</plugin> -->
    <plugin>transmission_interface/SimpleTransmission</plugin>
    <actuator name="motor_arm_base_joint" role="actuator1"/>
    <joint name="arm_base_joint" role="joint1">
      <mechanical_reduction>1.0</mechanical_reduction>
    </joint>
  </transmission>
  <transmission name="transmission_shoulder_joint">
    <!-- <plugin>transmission_interface/DifferentialTransmission</plugin> -->
    <plugin>transmission_interface/SimpleTransmission</plugin>
    <actuator name="motor_shoulder_joint" role="actuator1"/>
    <joint name="shoulder_joint" role="joint1">
      <mechanical_reduction>1.0</mechanical_reduction>
    </joint>
  </transmission>
  <transmission name="transmission_elbow_joint">
    <!-- <plugin>transmission_interface/DifferentialTransmission</plugin> -->
    <plugin>transmission_interface/SimpleTransmission</plugin>
    <actuator name="motor_elbow_joint" role="actuator1"/>
    <joint name="elbow_joint" role="joint1">
      <mechanical_reduction>1.0</mechanical_reduction>
    </joint>
  </transmission>
  <transmission name="transmission_wrist_joint">
    <!-- <plugin>transmission_interface/DifferentialTransmission</plugin> -->
    <plugin>transmission_interface/SimpleTransmission</plugin>
    <actuator name="motor_wrist_joint" role="actuator1"/>
    <joint name="wrist_joint" role="joint1">
      <mechanical_reduction>1.0</mechanical_reduction>
    </joint>
  </transmission>
  <transmission name="transmission_gripper_right_joint">
    <!-- <plugin>transmission_interface/DifferentialTransmission</plugin> -->
    <plugin>transmission_interface/SimpleTransmission</plugin>
    <actuator name="motor_gripper_right_joint" role="actuator1"/>
    <joint name="gripper_right_joint" role="joint1">
      <mechanical_reduction>1.0</mechanical_reduction>
    </joint>
  </transmission>
</robot>
